Workbook

Sheet Ty_le_chi_phi
A1: BẢNG TRA TỰ ĐỘNG PHÍ TƯ VẤN - CÔNG TRÌNH DÂN DỤNG
A2: Nhập giá trị gói xây lắp tại B7, chi phí thiết bị nếu có tại B8, cấp công trình tại B9. Tỷ lệ được nội suy theo Phụ lục VIII kèm theo Thông tư 12/2021/TT-BXD.
A3: Nguồn: qlda.gxd.vn - Bảng 1.1, 2.5, 2.16, 2.21 của Phụ lục VIII TT 12/2021/TT-BXD.
A5: I. THÔNG SỐ ĐẦU VÀO
A6: Chỉ tiêu | B6: Giá trị | C6: Đơn vị | D6: Ghi chú
A7: Giá trị gói xây lắp | B7: 9000000000 | C7: VND | D7: Chi phí xây dựng chưa VAT
A8: Chi phí thiết bị (nếu có) | B8: 0 | C8: VND | D8: Dùng cho QLDA theo chi phí xây dựng + thiết bị; mặc định 0
A9: Cấp công trình dân dụng | B9: Cấp III | D9: Nhập: Cấp đặc biệt, Cấp I, Cấp II, Cấp III, Cấp IV
A10: Tỷ lệ VAT đầu ra | B10: =Dau_vao!B21 -> 0.08 | C10: % | D10: Liên kết từ Dau_vao!B21
A11: Quy mô chi phí xây dựng | B11: =B7/1000000000 -> 9 | C11: tỷ đồng | D11: Dùng cho thiết kế, giám sát, thẩm tra thiết kế
A12: Quy mô chi phí xây dựng + thiết bị | B12: =(B7+B8)/1000000000 -> 9 | C12: tỷ đồng | D12: Dùng cho quản lý dự án
A14: II. BẢNG TÍNH CHI PHÍ TƯ VẤN
A15: Hạng mục | B15: Cơ sở tính | C15: Tỷ lệ định mức | D15: Chi phí chưa VAT | E15: VAT | F15: Tổng có VAT | G15: Nguồn/Ghi chú
A16: Tư vấn giám sát thi công xây dựng | B16: =$B$7 -> 9000000000 | C16: {=IF($B$11<=MIN($A$59:$A$69),INDEX($B$59:$B$69,1)/100,IF($B$11>=MAX($A$59:$A$69),INDEX($B$59:$B$69,ROWS($B$59:$B$69))/100,(INDEX($B$59:$B$69,MATCH($B$11,$A$59:$A$69,1))+(INDEX($B$59:$B$69,MATCH($B$11,$A$59:$A$69,1)+1)-INDEX($B$59:$B$69,MATCH($B$11,$A$59:$A$69,1)))*(($B$11-INDEX($A$59:$A$69,MATCH($B$11,$A$59:$A$69,1)))/(INDEX($A$59:$A$69,MATCH($B$11,$A$59:$A$69,1)+1)-INDEX($A$59:$A$69,MATCH($B$11,$A$59:$A$69,1)))))/100))} -> 0.03285 | D16: =B16*C16 -> 295650000 | E16: =D16*$B$10 -> 23652000 | F16: =D16+E16 -> 319302000 | G16: Bảng 2.21
A17: Tư vấn thiết kế BVTC 2 bước | B17: =$B$7 -> 9000000000 | C17: {=IFERROR(IF($B$11<=MIN($A$44:$A$54),INDEX($B$44:$F$54,1,MATCH($B$9,$B$43:$F$43,0))/100,IF($B$11>=MAX($A$44:$A$54),INDEX($B$44:$F$54,ROWS($A$44:$A$54),MATCH($B$9,$B$43:$F$43,0))/100,(INDEX($B$44:$F$54,MATCH($B$11,$A$44:$A$54,1),MATCH($B$9,$B$43:$F$43,0))+(INDEX($B$44:$F$54,MATCH($B$11,$A$44:$A$54,1)+1,MATCH($B$9,$B$43:$F$43,0))-INDEX($B$44:$F$54,MATCH($B$11,$A$44:$A$54,1),MATCH($B$9,$B$43:$F$43,0)))*(($B$11-INDEX($A$44:$A$54,MATCH($B$11,$A$44:$A$54,1)))/(INDEX($A$44:$A$54,MATCH($B$11,$A$44:$A$54,1)+1)-INDEX($A$44:$A$54,MATCH($B$11,$A$44:$A$54,1)))))/100)),NA())} -> 0.0341 | D17: =B17*C17 -> 306900000 | E17: =D17*$B$10 -> 24552000 | F17: =D17+E17 -> 331452000 | G17: Bảng 2.5
A18: Quản lý dự án | B18: =$B$7+$B$8 -> 9000000000 | C18: {=IF($B$12<=MIN($A$73:$A$84),INDEX($B$73:$B$84,1)/100,IF($B$12>=MAX($A$73:$A$84),INDEX($B$73:$B$84,ROWS($B$73:$B$84))/100,(INDEX($B$73:$B$84,MATCH($B$12,$A$73:$A$84,1))+(INDEX($B$73:$B$84,MATCH($B$12,$A$73:$A$84,1)+1)-INDEX($B$73:$B$84,MATCH($B$12,$A$73:$A$84,1)))*(($B$12-INDEX($A$73:$A$84,MATCH($B$12,$A$73:$A$84,1)))/(INDEX($A$73:$A$84,MATCH($B$12,$A$73:$A$84,1)+1)-INDEX($A$73:$A$84,MATCH($B$12,$A$73:$A$84,1)))))/100))} -> 0.03446 | D18: =B18*C18 -> 310140000 | E18: =D18*$B$10 -> 24811200 | F18: =D18+E18 -> 334951200 | G18: Bảng 1.1 - theo XD+TB
A19: Thẩm tra thiết kế xây dựng | B19: =$B$7 -> 9000000000 | C19: {=IF($B$11<=MIN($A$88:$A$98),INDEX($B$88:$B$98,1)/100,IF($B$11>=MAX($A$88:$A$98),INDEX($B$88:$B$98,ROWS($B$88:$B$98))/100,(INDEX($B$88:$B$98,MATCH($B$11,$A$88:$A$98,1))+(INDEX($B$88:$B$98,MATCH($B$11,$A$88:$A$98,1)+1)-INDEX($B$88:$B$98,MATCH($B$11,$A$88:$A$98,1)))*(($B$11-INDEX($A$88:$A$98,MATCH($B$11,$A$88:$A$98,1)))/(INDEX($A$88:$A$98,MATCH($B$11,$A$88:$A$98,1)+1)-INDEX($A$88:$A$98,MATCH($B$11,$A$88:$A$98,1)))))/100))} -> 0.00258 | D19: =MAX(B19*C19,2000000) -> 23220000 | E19: =D19*$B$10 -> 1857600 | F19: =D19+E19 -> 25077600 | G19: Bảng 2.16 - tối thiểu 2 triệu đồng
A20: Tổng cộng | D20: =SUM(D16:D19) -> 935910000 | E20: =SUM(E16:E19) -> 74872800 | F20: =SUM(F16:F19) -> 1010782800 | G20: Tổng 4 hạng mục
A21: Tổng chưa VAT (triệu đồng) | D21: =D20/1000000 -> 935.91 | F21: =F20/1000000 -> 1010.7828 | G21: Cột D: chưa VAT; Cột F: có VAT
A24: III. BẢNG ĐỘ NHẠY THEO GIÁ TRỊ GÓI XÂY LẮP
A25: Giá trị XL | B25: Giám sát | C25: Thiết kế | D25: QLDA | E25: Thẩm tra TK | F25: Tổng chưa VAT | G25: Tổng có VAT
A26: 10000000000 | B26: =A26*(IF(A26/1000000000<=MIN($A$59:$A$69),INDEX($B$59:$B$69,1)/100,IF(A26/1000000000>=MAX($A$59:$A$69),INDEX($B$59:$B$69,ROWS($B$59:$B$69))/100,(INDEX($B$59:$B$69,MATCH(A26/1000000000,$A$59:$A$69,1))+(INDEX($B$59:$B$69,MATCH(A26/1000000000,$A$59:$A$69,1)+1)-INDEX($B$59:$B$69,MATCH(A26/1000000000,$A$59:$A$69,1)))*((A26/1000000000-INDEX($A$59:$A$69,MATCH(A26/1000000000,$A$59:$A$69,1)))/(INDEX($A$59:$A$69,MATCH(A26/1000000000,$A$59:$A$69,1)+1)-INDEX($A$59:$A$69,MATCH(A26/1000000000,$A$59:$A$69,1)))))/100))) -> 328500000 | C26: =A26*(IFERROR(IF(A26/1000000000<=MIN($A$44:$A$54),INDEX($B$44:$F$54,1,MATCH($B$9,$B$43:$F$43,0))/100,IF(A26/1000000000>=MAX($A$44:$A$54),INDEX($B$44:$F$54,ROWS($A$44:$A$54),MATCH($B$9,$B$43:$F$43,0))/100,(INDEX($B$44:$F$54,MATCH(A26/1000000000,$A$44:$A$54,1),MATCH($B$9,$B$43:$F$43,0))+(INDEX($B$44:$F$54,MATCH(A26/1000000000,$A$44:$A$54,1)+1,MATCH($B$9,$B$43:$F$43,0))-INDEX($B$44:$F$54,MATCH(A26/1000000000,$A$44:$A$54,1),MATCH($B$9,$B$43:$F$43,0)))*((A26/1000000000-INDEX($A$44:$A$54,MATCH(A26/1000000000,$A$44:$A$54,1)))/(INDEX($A$44:$A$54,MATCH(A26/1000000000,$A$44:$A$54,1)+1)-INDEX($A$44:$A$54,MATCH(A26/1000000000,$A$44:$A$54,1)))))/100)),NA())) -> 341000000 | D26: =(A26+$B$8)*(IF((A26+$B$8)/1000000000<=MIN($A$73:$A$84),INDEX($B$73:$B$84,1)/100,IF((A26+$B$8)/1000000000>=MAX($A$73:$A$84),INDEX($B$73:$B$84,ROWS($B$73:$B$84))/100,(INDEX($B$73:$B$84,MATCH((A26+$B$8)/1000000000,$A$73:$A$84,1))+(INDEX($B$73:$B$84,MATCH((A26+$B$8)/1000000000,$A$73:$A$84,1)+1)-INDEX($B$73:$B$84,MATCH((A26+$B$8)/1000000000,$A$73:$A$84,1)))*(((A26+$B$8)/1000000000-INDEX($A$73:$A$84,MATCH((A26+$B$8)/1000000000,$A$73:$A$84,1)))/(INDEX($A$73:$A$84,MATCH((A26+$B$8)/1000000000,$A$73:$A$84,1)+1)-INDEX($A$73:$A$84,MATCH((A26+$B$8)/1000000000,$A$73:$A$84,1)))))/100))) -> 344600000 | E26: =MAX(A26*(IF(A26/1000000000<=MIN($A$88:$A$98),INDEX($B$88:$B$98,1)/100,IF(A26/1000000000>=MAX($A$88:$A$98),INDEX($B$88:$B$98,ROWS($B$88:$B$98))/100,(INDEX($B$88:$B$98,MATCH(A26/1000000000,$A$88:$A$98,1))+(INDEX($B$88:$B$98,MATCH(A26/1000000000,$A$88:$A$98,1)+1)-INDEX($B$88:$B$98,MATCH(A26/1000000000,$A$88:$A$98,1)))*((A26/1000000000-INDEX($A$88:$A$98,MATCH(A26/1000000000,$A$88:$A$98,1)))/(INDEX($A$88:$A$98,MATCH(A26/1000000000,$A$88:$A$98,1)+1)-INDEX($A$88:$A$98,MATCH(A26/1000000000,$A$88:$A$98,1)))))/100))),2000000) -> 25800000 | F26: =SUM(B26:E26) -> 1039900000 | G26: =F26*(1+$B$10) -> 1123092000
A27: 20000000000 | B27: =A27*(IF(A27/1000000000<=MIN($A$59:$A$69),INDEX($B$59:$B$69,1)/100,IF(A27/1000000000>=MAX($A$59:$A$69),INDEX($B$59:$B$69,ROWS($B$59:$B$69))/100,(INDEX($B$59:$B$69,MATCH(A27/1000000000,$A$59:$A$69,1))+(INDEX($B$59:$B$69,MATCH(A27/1000000000,$A$59:$A$69,1)+1)-INDEX($B$59:$B$69,MATCH(A27/1000000000,$A$59:$A$69,1)))*((A27/1000000000-INDEX($A$59:$A$69,MATCH(A27/1000000000,$A$59:$A$69,1)))/(INDEX($A$59:$A$69,MATCH(A27/1000000000,$A$59:$A$69,1)+1)-INDEX($A$59:$A$69,MATCH(A27/1000000000,$A$59:$A$69,1)))))/100))) -> 570600000 | C27: =A27*(IFERROR(IF(A27/1000000000<=MIN($A$44:$A$54),INDEX($B$44:$F$54,1,MATCH($B$9,$B$43:$F$43,0))/100,IF(A27/1000000000>=MAX($A$44:$A$54),INDEX($B$44:$F$54,ROWS($A$44:$A$54),MATCH($B$9,$B$43:$F$43,0))/100,(INDEX($B$44:$F$54,MATCH(A27/1000000000,$A$44:$A$54,1),MATCH($B$9,$B$43:$F$43,0))+(INDEX($B$44:$F$54,MATCH(A27/1000000000,$A$44:$A$54,1)+1,MATCH($B$9,$B$43:$F$43,0))-INDEX($B$44:$F$54,MATCH(A27/1000000000,$A$44:$A$54,1),MATCH($B$9,$B$43:$F$43,0)))*((A27/1000000000-INDEX($A$44:$A$54,MATCH(A27/1000000000,$A$44:$A$54,1)))/(INDEX($A$44:$A$54,MATCH(A27/1000000000,$A$44:$A$54,1)+1)-INDEX($A$44:$A$54,MATCH(A27/1000000000,$A$44:$A$54,1)))))/100)),NA())) -> 590000000 | D27: =(A27+$B$8)*(IF((A27+$B$8)/1000000000<=MIN($A$73:$A$84),INDEX($B$73:$B$84,1)/100,IF((A27+$B$8)/1000000000>=MAX($A$73:$A$84),INDEX($B$73:$B$84,ROWS($B$73:$B$84))/100,(INDEX($B$73:$B$84,MATCH((A27+$B$8)/1000000000,$A$73:$A$84,1))+(INDEX($B$73:$B$84,MATCH((A27+$B$8)/1000000000,$A$73:$A$84,1)+1)-INDEX($B$73:$B$84,MATCH((A27+$B$8)/1000000000,$A$73:$A$84,1)))*(((A27+$B$8)/1000000000-INDEX($A$73:$A$84,MATCH((A27+$B$8)/1000000000,$A$73:$A$84,1)))/(INDEX($A$73:$A$84,MATCH((A27+$B$8)/1000000000,$A$73:$A$84,1)+1)-INDEX($A$73:$A$84,MATCH((A27+$B$8)/1000000000,$A$73:$A$84,1)))))/100))) -> 584600000 | E27: =MAX(A27*(IF(A27/1000000000<=MIN($A$88:$A$98),INDEX($B$88:$B$98,1)/100,IF(A27/1000000000>=MAX($A$88:$A$98),INDEX($B$88:$B$98,ROWS($B$88:$B$98))/100,(INDEX($B$88:$B$98,MATCH(A27/1000000000,$A$88:$A$98,1))+(INDEX($B$88:$B$98,MATCH(A27/1000000000,$A$88:$A$98,1)+1)-INDEX($B$88:$B$98,MATCH(A27/1000000000,$A$88:$A$98,1)))*((A27/1000000000-INDEX($A$88:$A$98,MATCH(A27/1000000000,$A$88:$A$98,1)))/(INDEX($A$88:$A$98,MATCH(A27/1000000000,$A$88:$A$98,1)+1)-INDEX($A$88:$A$98,MATCH(A27/1000000000,$A$88:$A$98,1)))))/100))),2000000) -> 44600000 | F27: =SUM(B27:E27) -> 1789800000 | G27: =F27*(1+$B$10) -> 1932984000
A28: 30000000000 | B28: =A28*(IF(A28/1000000000<=MIN($A$59:$A$69),INDEX($B$59:$B$69,1)/100,IF(A28/1000000000>=MAX($A$59:$A$69),INDEX($B$59:$B$69,ROWS($B$59:$B$69))/100,(INDEX($B$59:$B$69,MATCH(A28/1000000000,$A$59:$A$69,1))+(INDEX($B$59:$B$69,MATCH(A28/1000000000,$A$59:$A$69,1)+1)-INDEX($B$59:$B$69,MATCH(A28/1000000000,$A$59:$A$69,1)))*((A28/1000000000-INDEX($A$59:$A$69,MATCH(A28/1000000000,$A$59:$A$69,1)))/(INDEX($A$59:$A$69,MATCH(A28/1000000000,$A$59:$A$69,1)+1)-INDEX($A$59:$A$69,MATCH(A28/1000000000,$A$59:$A$69,1)))))/100))) -> 814100000 | C28: =A28*(IFERROR(IF(A28/1000000000<=MIN($A$44:$A$54),INDEX($B$44:$F$54,1,MATCH($B$9,$B$43:$F$43,0))/100,IF(A28/1000000000>=MAX($A$44:$A$54),INDEX($B$44:$F$54,ROWS($A$44:$A$54),MATCH($B$9,$B$43:$F$43,0))/100,(INDEX($B$44:$F$54,MATCH(A28/1000000000,$A$44:$A$54,1),MATCH($B$9,$B$43:$F$43,0))+(INDEX($B$44:$F$54,MATCH(A28/1000000000,$A$44:$A$54,1)+1,MATCH($B$9,$B$43:$F$43,0))-INDEX($B$44:$F$54,MATCH(A28/1000000000,$A$44:$A$54,1),MATCH($B$9,$B$43:$F$43,0)))*((A28/1000000000-INDEX($A$44:$A$54,MATCH(A28/1000000000,$A$44:$A$54,1)))/(INDEX($A$44:$A$54,MATCH(A28/1000000000,$A$44:$A$54,1)+1)-INDEX($A$44:$A$54,MATCH(A28/1000000000,$A$44:$A$54,1)))))/100)),NA())) -> 838000000 | D28: =(A28+$B$8)*(IF((A28+$B$8)/1000000000<=MIN($A$73:$A$84),INDEX($B$73:$B$84,1)/100,IF((A28+$B$8)/1000000000>=MAX($A$73:$A$84),INDEX($B$73:$B$84,ROWS($B$73:$B$84))/100,(INDEX($B$73:$B$84,MATCH((A28+$B$8)/1000000000,$A$73:$A$84,1))+(INDEX($B$73:$B$84,MATCH((A28+$B$8)/1000000000,$A$73:$A$84,1)+1)-INDEX($B$73:$B$84,MATCH((A28+$B$8)/1000000000,$A$73:$A$84,1)))*(((A28+$B$8)/1000000000-INDEX($A$73:$A$84,MATCH((A28+$B$8)/1000000000,$A$73:$A$84,1)))/(INDEX($A$73:$A$84,MATCH((A28+$B$8)/1000000000,$A$73:$A$84,1)+1)-INDEX($A$73:$A$84,MATCH((A28+$B$8)/1000000000,$A$73:$A$84,1)))))/100))) -> 845600000 | E28: =MAX(A28*(IF(A28/1000000000<=MIN($A$88:$A$98),INDEX($B$88:$B$98,1)/100,IF(A28/1000000000>=MAX($A$88:$A$98),INDEX($B$88:$B$98,ROWS($B$88:$B$98))/100,(INDEX($B$88:$B$98,MATCH(A28/1000000000,$A$88:$A$98,1))+(INDEX($B$88:$B$98,MATCH(A28/1000000000,$A$88:$A$98,1)+1)-INDEX($B$88:$B$98,MATCH(A28/1000000000,$A$88:$A$98,1)))*((A28/1000000000-INDEX($A$88:$A$98,MATCH(A28/1000000000,$A$88:$A$98,1)))/(INDEX($A$88:$A$98,MATCH(A28/1000000000,$A$88:$A$98,1)+1)-INDEX($A$88:$A$98,MATCH(A28/1000000000,$A$88:$A$98,1)))))/100))),2000000) -> 61800000 | F28: =SUM(B28:E28) -> 2559500000 | G28: =F28*(1+$B$10) -> 2764260000
A29: 40000000000 | B29: =A29*(IF(A29/1000000000<=MIN($A$59:$A$69),INDEX($B$59:$B$69,1)/100,IF(A29/1000000000>=MAX($A$59:$A$69),INDEX($B$59:$B$69,ROWS($B$59:$B$69))/100,(INDEX($B$59:$B$69,MATCH(A29/1000000000,$A$59:$A$69,1))+(INDEX($B$59:$B$69,MATCH(A29/1000000000,$A$59:$A$69,1)+1)-INDEX($B$59:$B$69,MATCH(A29/1000000000,$A$59:$A$69,1)))*((A29/1000000000-INDEX($A$59:$A$69,MATCH(A29/1000000000,$A$59:$A$69,1)))/(INDEX($A$59:$A$69,MATCH(A29/1000000000,$A$59:$A$69,1)+1)-INDEX($A$59:$A$69,MATCH(A29/1000000000,$A$59:$A$69,1)))))/100))) -> 1029733333 | C29: =A29*(IFERROR(IF(A29/1000000000<=MIN($A$44:$A$54),INDEX($B$44:$F$54,1,MATCH($B$9,$B$43:$F$43,0))/100,IF(A29/1000000000>=MAX($A$44:$A$54),INDEX($B$44:$F$54,ROWS($A$44:$A$54),MATCH($B$9,$B$43:$F$43,0))/100,(INDEX($B$44:$F$54,MATCH(A29/1000000000,$A$44:$A$54,1),MATCH($B$9,$B$43:$F$43,0))+(INDEX($B$44:$F$54,MATCH(A29/1000000000,$A$44:$A$54,1)+1,MATCH($B$9,$B$43:$F$43,0))-INDEX($B$44:$F$54,MATCH(A29/1000000000,$A$44:$A$54,1),MATCH($B$9,$B$43:$F$43,0)))*((A29/1000000000-INDEX($A$44:$A$54,MATCH(A29/1000000000,$A$44:$A$54,1)))/(INDEX($A$44:$A$54,MATCH(A29/1000000000,$A$44:$A$54,1)+1)-INDEX($A$44:$A$54,MATCH(A29/1000000000,$A$44:$A$54,1)))))/100)),NA())) -> 1054666667 | D29: =(A29+$B$8)*(IF((A29+$B$8)/1000000000<=MIN($A$73:$A$84),INDEX($B$73:$B$84,1)/100,IF((A29+$B$8)/1000000000>=MAX($A$73:$A$84),INDEX($B$73:$B$84,ROWS($B$73:$B$84))/100,(INDEX($B$73:$B$84,MATCH((A29+$B$8)/1000000000,$A$73:$A$84,1))+(INDEX($B$73:$B$84,MATCH((A29+$B$8)/1000000000,$A$73:$A$84,1)+1)-INDEX($B$73:$B$84,MATCH((A29+$B$8)/1000000000,$A$73:$A$84,1)))*(((A29+$B$8)/1000000000-INDEX($A$73:$A$84,MATCH((A29+$B$8)/1000000000,$A$73:$A$84,1)))/(INDEX($A$73:$A$84,MATCH((A29+$B$8)/1000000000,$A$73:$A$84,1)+1)-INDEX($A$73:$A$84,MATCH((A29+$B$8)/1000000000,$A$73:$A$84,1)))))/100))) -> 1085733333 | E29: =MAX(A29*(IF(A29/1000000000<=MIN($A$88:$A$98),INDEX($B$88:$B$98,1)/100,IF(A29/1000000000>=MAX($A$88:$A$98),INDEX($B$88:$B$98,ROWS($B$88:$B$98))/100,(INDEX($B$88:$B$98,MATCH(A29/1000000000,$A$88:$A$98,1))+(INDEX($B$88:$B$98,MATCH(A29/1000000000,$A$88:$A$98,1)+1)-INDEX($B$88:$B$98,MATCH(A29/1000000000,$A$88:$A$98,1)))*((A29/1000000000-INDEX($A$88:$A$98,MATCH(A29/1000000000,$A$88:$A$98,1)))/(INDEX($A$88:$A$98,MATCH(A29/1000000000,$A$88:$A$98,1)+1)-INDEX($A$88:$A$98,MATCH(A29/1000000000,$A$88:$A$98,1)))))/100))),2000000) -> 75600000 | F29: =SUM(B29:E29) -> 3245733333 | G29: =F29*(1+$B$10) -> 3505392000
A30: 50000000000 | B30: =A30*(IF(A30/1000000000<=MIN($A$59:$A$69),INDEX($B$59:$B$69,1)/100,IF(A30/1000000000>=MAX($A$59:$A$69),INDEX($B$59:$B$69,ROWS($B$59:$B$69))/100,(INDEX($B$59:$B$69,MATCH(A30/1000000000,$A$59:$A$69,1))+(INDEX($B$59:$B$69,MATCH(A30/1000000000,$A$59:$A$69,1)+1)-INDEX($B$59:$B$69,MATCH(A30/1000000000,$A$59:$A$69,1)))*((A30/1000000000-INDEX($A$59:$A$69,MATCH(A30/1000000000,$A$59:$A$69,1)))/(INDEX($A$59:$A$69,MATCH(A30/1000000000,$A$59:$A$69,1)+1)-INDEX($A$59:$A$69,MATCH(A30/1000000000,$A$59:$A$69,1)))))/100))) -> 1217500000 | C30: =A30*(IFERROR(IF(A30/1000000000<=MIN($A$44:$A$54),INDEX($B$44:$F$54,1,MATCH($B$9,$B$43:$F$43,0))/100,IF(A30/1000000000>=MAX($A$44:$A$54),INDEX($B$44:$F$54,ROWS($A$44:$A$54),MATCH($B$9,$B$43:$F$43,0))/100,(INDEX($B$44:$F$54,MATCH(A30/1000000000,$A$44:$A$54,1),MATCH($B$9,$B$43:$F$43,0))+(INDEX($B$44:$F$54,MATCH(A30/1000000000,$A$44:$A$54,1)+1,MATCH($B$9,$B$43:$F$43,0))-INDEX($B$44:$F$54,MATCH(A30/1000000000,$A$44:$A$54,1),MATCH($B$9,$B$43:$F$43,0)))*((A30/1000000000-INDEX($A$44:$A$54,MATCH(A30/1000000000,$A$44:$A$54,1)))/(INDEX($A$44:$A$54,MATCH(A30/1000000000,$A$44:$A$54,1)+1)-INDEX($A$44:$A$54,MATCH(A30/1000000000,$A$44:$A$54,1)))))/100)),NA())) -> 1240000000 | D30: =(A30+$B$8)*(IF((A30+$B$8)/1000000000<=MIN($A$73:$A$84),INDEX($B$73:$B$84,1)/100,IF((A30+$B$8)/1000000000>=MAX($A$73:$A$84),INDEX($B$73:$B$84,ROWS($B$73:$B$84))/100,(INDEX($B$73:$B$84,MATCH((A30+$B$8)/1000000000,$A$73:$A$84,1))+(INDEX($B$73:$B$84,MATCH((A30+$B$8)/1000000000,$A$73:$A$84,1)+1)-INDEX($B$73:$B$84,MATCH((A30+$B$8)/1000000000,$A$73:$A$84,1)))*(((A30+$B$8)/1000000000-INDEX($A$73:$A$84,MATCH((A30+$B$8)/1000000000,$A$73:$A$84,1)))/(INDEX($A$73:$A$84,MATCH((A30+$B$8)/1000000000,$A$73:$A$84,1)+1)-INDEX($A$73:$A$84,MATCH((A30+$B$8)/1000000000,$A$73:$A$84,1)))))/100))) -> 1305000000 | E30: =MAX(A30*(IF(A30/1000000000<=MIN($A$88:$A$98),INDEX($B$88:$B$98,1)/100,IF(A30/1000000000>=MAX($A$88:$A$98),INDEX($B$88:$B$98,ROWS($B$88:$B$98))/100,(INDEX($B$88:$B$98,MATCH(A30/1000000000,$A$88:$A$98,1))+(INDEX($B$88:$B$98,MATCH(A30/1000000000,$A$88:$A$98,1)+1)-INDEX($B$88:$B$98,MATCH(A30/1000000000,$A$88:$A$98,1)))*((A30/1000000000-INDEX($A$88:$A$98,MATCH(A30/1000000000,$A$88:$A$98,1)))/(INDEX($A$88:$A$98,MATCH(A30/1000000000,$A$88:$A$98,1)+1)-INDEX($A$88:$A$98,MATCH(A30/1000000000,$A$88:$A$98,1)))))/100))),2000000) -> 86000000 | F30: =SUM(B30:E30) -> 3848500000 | G30: =F30*(1+$B$10) -> 4156380000
A31: 60000000000 | B31: =A31*(IF(A31/1000000000<=MIN($A$59:$A$69),INDEX($B$59:$B$69,1)/100,IF(A31/1000000000>=MAX($A$59:$A$69),INDEX($B$59:$B$69,ROWS($B$59:$B$69))/100,(INDEX($B$59:$B$69,MATCH(A31/1000000000,$A$59:$A$69,1))+(INDEX($B$59:$B$69,MATCH(A31/1000000000,$A$59:$A$69,1)+1)-INDEX($B$59:$B$69,MATCH(A31/1000000000,$A$59:$A$69,1)))*((A31/1000000000-INDEX($A$59:$A$69,MATCH(A31/1000000000,$A$59:$A$69,1)))/(INDEX($A$59:$A$69,MATCH(A31/1000000000,$A$59:$A$69,1)+1)-INDEX($A$59:$A$69,MATCH(A31/1000000000,$A$59:$A$69,1)))))/100))) -> 1390200000 | C31: =A31*(IFERROR(IF(A31/1000000000<=MIN($A$44:$A$54),INDEX($B$44:$F$54,1,MATCH($B$9,$B$43:$F$43,0))/100,IF(A31/1000000000>=MAX($A$44:$A$54),INDEX($B$44:$F$54,ROWS($A$44:$A$54),MATCH($B$9,$B$43:$F$43,0))/100,(INDEX($B$44:$F$54,MATCH(A31/1000000000,$A$44:$A$54,1),MATCH($B$9,$B$43:$F$43,0))+(INDEX($B$44:$F$54,MATCH(A31/1000000000,$A$44:$A$54,1)+1,MATCH($B$9,$B$43:$F$43,0))-INDEX($B$44:$F$54,MATCH(A31/1000000000,$A$44:$A$54,1),MATCH($B$9,$B$43:$F$43,0)))*((A31/1000000000-INDEX($A$44:$A$54,MATCH(A31/1000000000,$A$44:$A$54,1)))/(INDEX($A$44:$A$54,MATCH(A31/1000000000,$A$44:$A$54,1)+1)-INDEX($A$44:$A$54,MATCH(A31/1000000000,$A$44:$A$54,1)))))/100)),NA())) -> 1460400000 | D31: =(A31+$B$8)*(IF((A31+$B$8)/1000000000<=MIN($A$73:$A$84),INDEX($B$73:$B$84,1)/100,IF((A31+$B$8)/1000000000>=MAX($A$73:$A$84),INDEX($B$73:$B$84,ROWS($B$73:$B$84))/100,(INDEX($B$73:$B$84,MATCH((A31+$B$8)/1000000000,$A$73:$A$84,1))+(INDEX($B$73:$B$84,MATCH((A31+$B$8)/1000000000,$A$73:$A$84,1)+1)-INDEX($B$73:$B$84,MATCH((A31+$B$8)/1000000000,$A$73:$A$84,1)))*(((A31+$B$8)/1000000000-INDEX($A$73:$A$84,MATCH((A31+$B$8)/1000000000,$A$73:$A$84,1)))/(INDEX($A$73:$A$84,MATCH((A31+$B$8)/1000000000,$A$73:$A$84,1)+1)-INDEX($A$73:$A$84,MATCH((A31+$B$8)/1000000000,$A$73:$A$84,1)))))/100))) -> 1494840000 | E31: =MAX(A31*(IF(A31/1000000000<=MIN($A$88:$A$98),INDEX($B$88:$B$98,1)/100,IF(A31/1000000000>=MAX($A$88:$A$98),INDEX($B$88:$B$98,ROWS($B$88:$B$98))/100,(INDEX($B$88:$B$98,MATCH(A31/1000000000,$A$88:$A$98,1))+(INDEX($B$88:$B$98,MATCH(A31/1000000000,$A$88:$A$98,1)+1)-INDEX($B$88:$B$98,MATCH(A31/1000000000,$A$88:$A$98,1)))*((A31/1000000000-INDEX($A$88:$A$98,MATCH(A31/1000000000,$A$88:$A$98,1)))/(INDEX($A$88:$A$98,MATCH(A31/1000000000,$A$88:$A$98,1)+1)-INDEX($A$88:$A$98,MATCH(A31/1000000000,$A$88:$A$98,1)))))/100))),2000000) -> 99720000 | F31: =SUM(B31:E31) -> 4445160000 | G31: =F31*(1+$B$10) -> 4800772800
A32: 70000000000 | B32: =A32*(IF(A32/1000000000<=MIN($A$59:$A$69),INDEX($B$59:$B$69,1)/100,IF(A32/1000000000>=MAX($A$59:$A$69),INDEX($B$59:$B$69,ROWS($B$59:$B$69))/100,(INDEX($B$59:$B$69,MATCH(A32/1000000000,$A$59:$A$69,1))+(INDEX($B$59:$B$69,MATCH(A32/1000000000,$A$59:$A$69,1)+1)-INDEX($B$59:$B$69,MATCH(A32/1000000000,$A$59:$A$69,1)))*((A32/1000000000-INDEX($A$59:$A$69,MATCH(A32/1000000000,$A$59:$A$69,1)))/(INDEX($A$59:$A$69,MATCH(A32/1000000000,$A$59:$A$69,1)+1)-INDEX($A$59:$A$69,MATCH(A32/1000000000,$A$59:$A$69,1)))))/100))) -> 1539300000 | C32: =A32*(IFERROR(IF(A32/1000000000<=MIN($A$44:$A$54),INDEX($B$44:$F$54,1,MATCH($B$9,$B$43:$F$43,0))/100,IF(A32/1000000000>=MAX($A$44:$A$54),INDEX($B$44:$F$54,ROWS($A$44:$A$54),MATCH($B$9,$B$43:$F$43,0))/100,(INDEX($B$44:$F$54,MATCH(A32/1000000000,$A$44:$A$54,1),MATCH($B$9,$B$43:$F$43,0))+(INDEX($B$44:$F$54,MATCH(A32/1000000000,$A$44:$A$54,1)+1,MATCH($B$9,$B$43:$F$43,0))-INDEX($B$44:$F$54,MATCH(A32/1000000000,$A$44:$A$54,1),MATCH($B$9,$B$43:$F$43,0)))*((A32/1000000000-INDEX($A$44:$A$54,MATCH(A32/1000000000,$A$44:$A$54,1)))/(INDEX($A$44:$A$54,MATCH(A32/1000000000,$A$44:$A$54,1)+1)-INDEX($A$44:$A$54,MATCH(A32/1000000000,$A$44:$A$54,1)))))/100)),NA())) -> 1671600000 | D32: =(A32+$B$8)*(IF((A32+$B$8)/1000000000<=MIN($A$73:$A$84),INDEX($B$73:$B$84,1)/100,IF((A32+$B$8)/1000000000>=MAX($A$73:$A$84),INDEX($B$73:$B$84,ROWS($B$73:$B$84))/100,(INDEX($B$73:$B$84,MATCH((A32+$B$8)/1000000000,$A$73:$A$84,1))+(INDEX($B$73:$B$84,MATCH((A32+$B$8)/1000000000,$A$73:$A$84,1)+1)-INDEX($B$73:$B$84,MATCH((A32+$B$8)/1000000000,$A$73:$A$84,1)))*(((A32+$B$8)/1000000000-INDEX($A$73:$A$84,MATCH((A32+$B$8)/1000000000,$A$73:$A$84,1)))/(INDEX($A$73:$A$84,MATCH((A32+$B$8)/1000000000,$A$73:$A$84,1)+1)-INDEX($A$73:$A$84,MATCH((A32+$B$8)/1000000000,$A$73:$A$84,1)))))/100))) -> 1660960000 | E32: =MAX(A32*(IF(A32/1000000000<=MIN($A$88:$A$98),INDEX($B$88:$B$98,1)/100,IF(A32/1000000000>=MAX($A$88:$A$98),INDEX($B$88:$B$98,ROWS($B$88:$B$98))/100,(INDEX($B$88:$B$98,MATCH(A32/1000000000,$A$88:$A$98,1))+(INDEX($B$88:$B$98,MATCH(A32/1000000000,$A$88:$A$98,1)+1)-INDEX($B$88:$B$98,MATCH(A32/1000000000,$A$88:$A$98,1)))*((A32/1000000000-INDEX($A$88:$A$98,MATCH(A32/1000000000,$A$88:$A$98,1)))/(INDEX($A$88:$A$98,MATCH(A32/1000000000,$A$88:$A$98,1)+1)-INDEX($A$88:$A$98,MATCH(A32/1000000000,$A$88:$A$98,1)))))/100))),2000000) -> 112280000 | F32: =SUM(B32:E32) -> 4984140000 | G32: =F32*(1+$B$10) -> 5382871200
A33: 80000000000 | B33: =A33*(IF(A33/1000000000<=MIN($A$59:$A$69),INDEX($B$59:$B$69,1)/100,IF(A33/1000000000>=MAX($A$59:$A$69),INDEX($B$59:$B$69,ROWS($B$59:$B$69))/100,(INDEX($B$59:$B$69,MATCH(A33/1000000000,$A$59:$A$69,1))+(INDEX($B$59:$B$69,MATCH(A33/1000000000,$A$59:$A$69,1)+1)-INDEX($B$59:$B$69,MATCH(A33/1000000000,$A$59:$A$69,1)))*((A33/1000000000-INDEX($A$59:$A$69,MATCH(A33/1000000000,$A$59:$A$69,1)))/(INDEX($A$59:$A$69,MATCH(A33/1000000000,$A$59:$A$69,1)+1)-INDEX($A$59:$A$69,MATCH(A33/1000000000,$A$59:$A$69,1)))))/100))) -> 1664800000 | C33: =A33*(IFERROR(IF(A33/1000000000<=MIN($A$44:$A$54),INDEX($B$44:$F$54,1,MATCH($B$9,$B$43:$F$43,0))/100,IF(A33/1000000000>=MAX($A$44:$A$54),INDEX($B$44:$F$54,ROWS($A$44:$A$54),MATCH($B$9,$B$43:$F$43,0))/100,(INDEX($B$44:$F$54,MATCH(A33/1000000000,$A$44:$A$54,1),MATCH($B$9,$B$43:$F$43,0))+(INDEX($B$44:$F$54,MATCH(A33/1000000000,$A$44:$A$54,1)+1,MATCH($B$9,$B$43:$F$43,0))-INDEX($B$44:$F$54,MATCH(A33/1000000000,$A$44:$A$54,1),MATCH($B$9,$B$43:$F$43,0)))*((A33/1000000000-INDEX($A$44:$A$54,MATCH(A33/1000000000,$A$44:$A$54,1)))/(INDEX($A$44:$A$54,MATCH(A33/1000000000,$A$44:$A$54,1)+1)-INDEX($A$44:$A$54,MATCH(A33/1000000000,$A$44:$A$54,1)))))/100)),NA())) -> 1873600000 | D33: =(A33+$B$8)*(IF((A33+$B$8)/1000000000<=MIN($A$73:$A$84),INDEX($B$73:$B$84,1)/100,IF((A33+$B$8)/1000000000>=MAX($A$73:$A$84),INDEX($B$73:$B$84,ROWS($B$73:$B$84))/100,(INDEX($B$73:$B$84,MATCH((A33+$B$8)/1000000000,$A$73:$A$84,1))+(INDEX($B$73:$B$84,MATCH((A33+$B$8)/1000000000,$A$73:$A$84,1)+1)-INDEX($B$73:$B$84,MATCH((A33+$B$8)/1000000000,$A$73:$A$84,1)))*(((A33+$B$8)/1000000000-INDEX($A$73:$A$84,MATCH((A33+$B$8)/1000000000,$A$73:$A$84,1)))/(INDEX($A$73:$A$84,MATCH((A33+$B$8)/1000000000,$A$73:$A$84,1)+1)-INDEX($A$73:$A$84,MATCH((A33+$B$8)/1000000000,$A$73:$A$84,1)))))/100))) -> 1803360000 | E33: =MAX(A33*(IF(A33/1000000000<=MIN($A$88:$A$98),INDEX($B$88:$B$98,1)/100,IF(A33/1000000000>=MAX($A$88:$A$98),INDEX($B$88:$B$98,ROWS($B$88:$B$98))/100,(INDEX($B$88:$B$98,MATCH(A33/1000000000,$A$88:$A$98,1))+(INDEX($B$88:$B$98,MATCH(A33/1000000000,$A$88:$A$98,1)+1)-INDEX($B$88:$B$98,MATCH(A33/1000000000,$A$88:$A$98,1)))*((A33/1000000000-INDEX($A$88:$A$98,MATCH(A33/1000000000,$A$88:$A$98,1)))/(INDEX($A$88:$A$98,MATCH(A33/1000000000,$A$88:$A$98,1)+1)-INDEX($A$88:$A$98,MATCH(A33/1000000000,$A$88:$A$98,1)))))/100))),2000000) -> 123680000 | F33: =SUM(B33:E33) -> 5465440000 | G33: =F33*(1+$B$10) -> 5902675200
A34: 90000000000 | B34: =A34*(IF(A34/1000000000<=MIN($A$59:$A$69),INDEX($B$59:$B$69,1)/100,IF(A34/1000000000>=MAX($A$59:$A$69),INDEX($B$59:$B$69,ROWS($B$59:$B$69))/100,(INDEX($B$59:$B$69,MATCH(A34/1000000000,$A$59:$A$69,1))+(INDEX($B$59:$B$69,MATCH(A34/1000000000,$A$59:$A$69,1)+1)-INDEX($B$59:$B$69,MATCH(A34/1000000000,$A$59:$A$69,1)))*((A34/1000000000-INDEX($A$59:$A$69,MATCH(A34/1000000000,$A$59:$A$69,1)))/(INDEX($A$59:$A$69,MATCH(A34/1000000000,$A$59:$A$69,1)+1)-INDEX($A$59:$A$69,MATCH(A34/1000000000,$A$59:$A$69,1)))))/100))) -> 1766700000 | C34: =A34*(IFERROR(IF(A34/1000000000<=MIN($A$44:$A$54),INDEX($B$44:$F$54,1,MATCH($B$9,$B$43:$F$43,0))/100,IF(A34/1000000000>=MAX($A$44:$A$54),INDEX($B$44:$F$54,ROWS($A$44:$A$54),MATCH($B$9,$B$43:$F$43,0))/100,(INDEX($B$44:$F$54,MATCH(A34/1000000000,$A$44:$A$54,1),MATCH($B$9,$B$43:$F$43,0))+(INDEX($B$44:$F$54,MATCH(A34/1000000000,$A$44:$A$54,1)+1,MATCH($B$9,$B$43:$F$43,0))-INDEX($B$44:$F$54,MATCH(A34/1000000000,$A$44:$A$54,1),MATCH($B$9,$B$43:$F$43,0)))*((A34/1000000000-INDEX($A$44:$A$54,MATCH(A34/1000000000,$A$44:$A$54,1)))/(INDEX($A$44:$A$54,MATCH(A34/1000000000,$A$44:$A$54,1)+1)-INDEX($A$44:$A$54,MATCH(A34/1000000000,$A$44:$A$54,1)))))/100)),NA())) -> 2066400000 | D34: =(A34+$B$8)*(IF((A34+$B$8)/1000000000<=MIN($A$73:$A$84),INDEX($B$73:$B$84,1)/100,IF((A34+$B$8)/1000000000>=MAX($A$73:$A$84),INDEX($B$73:$B$84,ROWS($B$73:$B$84))/100,(INDEX($B$73:$B$84,MATCH((A34+$B$8)/1000000000,$A$73:$A$84,1))+(INDEX($B$73:$B$84,MATCH((A34+$B$8)/1000000000,$A$73:$A$84,1)+1)-INDEX($B$73:$B$84,MATCH((A34+$B$8)/1000000000,$A$73:$A$84,1)))*(((A34+$B$8)/1000000000-INDEX($A$73:$A$84,MATCH((A34+$B$8)/1000000000,$A$73:$A$84,1)))/(INDEX($A$73:$A$84,MATCH((A34+$B$8)/1000000000,$A$73:$A$84,1)+1)-INDEX($A$73:$A$84,MATCH((A34+$B$8)/1000000000,$A$73:$A$84,1)))))/100))) -> 1922040000 | E34: =MAX(A34*(IF(A34/1000000000<=MIN($A$88:$A$98),INDEX($B$88:$B$98,1)/100,IF(A34/1000000000>=MAX($A$88:$A$98),INDEX($B$88:$B$98,ROWS($B$88:$B$98))/100,(INDEX($B$88:$B$98,MATCH(A34/1000000000,$A$88:$A$98,1))+(INDEX($B$88:$B$98,MATCH(A34/1000000000,$A$88:$A$98,1)+1)-INDEX($B$88:$B$98,MATCH(A34/1000000000,$A$88:$A$98,1)))*((A34/1000000000-INDEX($A$88:$A$98,MATCH(A34/1000000000,$A$88:$A$98,1)))/(INDEX($A$88:$A$98,MATCH(A34/1000000000,$A$88:$A$98,1)+1)-INDEX($A$88:$A$98,MATCH(A34/1000000000,$A$88:$A$98,1)))))/100))),2000000) -> 133920000 | F34: =SUM(B34:E34) -> 5889060000 | G34: =F34*(1+$B$10) -> 6360184800
A35: 100000000000 | B35: =A35*(IF(A35/1000000000<=MIN($A$59:$A$69),INDEX($B$59:$B$69,1)/100,IF(A35/1000000000>=MAX($A$59:$A$69),INDEX($B$59:$B$69,ROWS($B$59:$B$69))/100,(INDEX($B$59:$B$69,MATCH(A35/1000000000,$A$59:$A$69,1))+(INDEX($B$59:$B$69,MATCH(A35/1000000000,$A$59:$A$69,1)+1)-INDEX($B$59:$B$69,MATCH(A35/1000000000,$A$59:$A$69,1)))*((A35/1000000000-INDEX($A$59:$A$69,MATCH(A35/1000000000,$A$59:$A$69,1)))/(INDEX($A$59:$A$69,MATCH(A35/1000000000,$A$59:$A$69,1)+1)-INDEX($A$59:$A$69,MATCH(A35/1000000000,$A$59:$A$69,1)))))/100))) -> 1845000000 | C35: =A35*(IFERROR(IF(A35/1000000000<=MIN($A$44:$A$54),INDEX($B$44:$F$54,1,MATCH($B$9,$B$43:$F$43,0))/100,IF(A35/1000000000>=MAX($A$44:$A$54),INDEX($B$44:$F$54,ROWS($A$44:$A$54),MATCH($B$9,$B$43:$F$43,0))/100,(INDEX($B$44:$F$54,MATCH(A35/1000000000,$A$44:$A$54,1),MATCH($B$9,$B$43:$F$43,0))+(INDEX($B$44:$F$54,MATCH(A35/1000000000,$A$44:$A$54,1)+1,MATCH($B$9,$B$43:$F$43,0))-INDEX($B$44:$F$54,MATCH(A35/1000000000,$A$44:$A$54,1),MATCH($B$9,$B$43:$F$43,0)))*((A35/1000000000-INDEX($A$44:$A$54,MATCH(A35/1000000000,$A$44:$A$54,1)))/(INDEX($A$44:$A$54,MATCH(A35/1000000000,$A$44:$A$54,1)+1)-INDEX($A$44:$A$54,MATCH(A35/1000000000,$A$44:$A$54,1)))))/100)),NA())) -> 2250000000 | D35: =(A35+$B$8)*(IF((A35+$B$8)/1000000000<=MIN($A$73:$A$84),INDEX($B$73:$B$84,1)/100,IF((A35+$B$8)/1000000000>=MAX($A$73:$A$84),INDEX($B$73:$B$84,ROWS($B$73:$B$84))/100,(INDEX($B$73:$B$84,MATCH((A35+$B$8)/1000000000,$A$73:$A$84,1))+(INDEX($B$73:$B$84,MATCH((A35+$B$8)/1000000000,$A$73:$A$84,1)+1)-INDEX($B$73:$B$84,MATCH((A35+$B$8)/1000000000,$A$73:$A$84,1)))*(((A35+$B$8)/1000000000-INDEX($A$73:$A$84,MATCH((A35+$B$8)/1000000000,$A$73:$A$84,1)))/(INDEX($A$73:$A$84,MATCH((A35+$B$8)/1000000000,$A$73:$A$84,1)+1)-INDEX($A$73:$A$84,MATCH((A35+$B$8)/1000000000,$A$73:$A$84,1)))))/100))) -> 2017000000 | E35: =MAX(A35*(IF(A35/1000000000<=MIN($A$88:$A$98),INDEX($B$88:$B$98,1)/100,IF(A35/1000000000>=MAX($A$88:$A$98),INDEX($B$88:$B$98,ROWS($B$88:$B$98))/100,(INDEX($B$88:$B$98,MATCH(A35/1000000000,$A$88:$A$98,1))+(INDEX($B$88:$B$98,MATCH(A35/1000000000,$A$88:$A$98,1)+1)-INDEX($B$88:$B$98,MATCH(A35/1000000000,$A$88:$A$98,1)))*((A35/1000000000-INDEX($A$88:$A$98,MATCH(A35/1000000000,$A$88:$A$98,1)))/(INDEX($A$88:$A$98,MATCH(A35/1000000000,$A$88:$A$98,1)+1)-INDEX($A$88:$A$98,MATCH(A35/1000000000,$A$88:$A$98,1)))))/100))),2000000) -> 143000000 | F35: =SUM(B35:E35) -> 6255000000 | G35: =F35*(1+$B$10) -> 6755400000
A42: IV. BẢNG 2.5 - TỶ LỆ THIẾT KẾ BVTC CÔNG TRÌNH DÂN DỤNG 2 BƯỚC
A43: Quy mô XL (tỷ đồng) | B43: Cấp đặc biệt | C43: Cấp I | D43: Cấp II | E43: Cấp III | F43: Cấp IV
A44: 10 | B44: 4.66 | C44: 4.22 | D44: 3.85 | E44: 3.41 | F44: 2.92
A45: 20 | B45: 4.05 | C45: 3.66 | D45: 3.33 | E45: 2.95 | F45: 2.55
A46: 50 | B46: 3.41 | C46: 3.1 | D46: 2.8 | E46: 2.48 | F46: 2.12
A47: 100 | B47: 3.1 | C47: 2.82 | D47: 2.54 | E47: 2.25 | F47: 1.86
A48: 200 | B48: 2.83 | C48: 2.57 | D48: 2.34 | E48: 2.07 | F48: 1.51
A49: 500 | B49: 2.39 | C49: 2.17 | D49: 1.98 | E49: 1.75 | F49: 1.3
A50: 1000 | B50: 1.93 | C50: 1.76 | D50: 1.61 | E50: 1.43 | F50: -
...

Sheet Dau_vao
A1: BẢNG 1 - ĐẦU VÀO
A2: Các ô màu vàng là đầu vào. Nhập giá trị chưa VAT trừ khi dòng ghi rõ là tỷ lệ.
A4: Thông số | B4: Giá trị
A5: Giá trị xây lắp/năm | B5: 30000000000
A6: Tỷ lệ phí tư vấn giám sát | B6: =Ty_le_chi_phi!C16 -> 0.03285
A7: Tỷ lệ phí tư vấn thiết kế | B7: =Ty_le_chi_phi!C17 -> 0.0341
A8: Tỷ lệ cắt lại cho chủ đầu tư - Hợp đồng loại 1 | B8: 0.55
A9: Tỷ lệ cắt lại cho chủ đầu tư - Hợp đồng loại 2 | B9: 0.35
A10: Thuế TNDN | B10: 0.17
A11: Tỷ lệ chi phí cố định được khấu trừ thuế | B11: 0.9
A12: Lương giám đốc/tháng | B12: 15000000
A13: Số kỹ thuật trực tiếp cho Loại 2 | B13: =IFERROR(FLOOR(B29/B14,1),0) -> 2
A14: Lương kỹ thuật trực tiếp/tháng | B14: 15000000
A15: Lương kế toán/tháng | B15: 3000000
A16: Thuê văn phòng/tháng | B16: 3000000
A17: Đi lại + tiếp khách/tháng | B17: 5000000
A18: Chi phí khác/tháng | B18: 3000000
A19: Tỷ lệ bảo hiểm DN đóng cho lao động trực tiếp | B19: 0.215
A20: Tỷ lệ chi phí lao động trực tiếp được khấu trừ thuế | B20: 1
A21: Tỷ lệ VAT đầu ra | B21: 0.08
A22: Tỷ lệ chi phí có hóa đơn VAT hợp lệ | B22: 1
A23: Chi phí ký hồ sơ (% doanh thu chưa VAT) - Loại 1 | B23: 0.05
A24: Tỷ lệ chi phí ký hồ sơ được khấu trừ thuế | B24: 0.9
A26: KIỂM TRA RÀNG BUỘC LƯƠNG KỸ THUẬT TRỰC TIẾP (HỢP ĐỒNG LOẠI 2)
A27: Tỷ lệ tối đa chi phí lương kỹ thuật trực tiếp / doanh thu (Loại 2) | B27: 0.2
A28: Quỹ lương kỹ thuật dự tính theo doanh thu (20%)/năm | B28: =B27*Tinh_toan!B6 -> 401700000
A29: Quỹ lương kỹ thuật dự tính theo doanh thu (20%)/tháng | B29: =B28/12 -> 33475000
A30: Quỹ lương kỹ thuật thực tế chi/năm | B30: =B13*B14*12 -> 360000000
A31: Quỹ lương kỹ thuật thực tế chi/tháng | B31: =B30/12 -> 30000000
A32: Tỷ lệ lương kỹ thuật thực tế / doanh thu | B32: =IF(Tinh_toan!B6=0,0,B30/Tinh_toan!B6) -> 0.17923824
A34: Chi phí ký hồ sơ (% doanh thu chưa VAT) - Loại 2 | B34: 0.02

Sheet Tinh_toan
A1: BẢNG 2 - TÍNH TOÁN TRUNG GIAN
A3: DOANH THU TƯ VẤN
A4: Doanh thu tư vấn giám sát | B4: =Dau_vao!B5*Dau_vao!B6 -> 985500000
A5: Doanh thu tư vấn thiết kế | B5: =Dau_vao!B5*Dau_vao!B7 -> 1023000000
A6: Tổng doanh thu tư vấn chưa VAT | B6: =SUM(B4:B5) -> 2008500000
A8: CHI PHÍ CỐ ĐỊNH CHUNG
A9: Thuê văn phòng/năm | B9: =Dau_vao!B16*12 -> 36000000
A10: Đi lại + tiếp khách/năm | B10: =Dau_vao!B17*12 -> 60000000
A11: Chi phí khác/năm | B11: =Dau_vao!B18*12 -> 36000000
A12: Tổng chi phí cố định thực chi | B12: =SUM(B9:B11) -> 132000000
A13: Chi phí cố định được khấu trừ thuế | B13: =B12*Dau_vao!B11 -> 118800000
A15: CHI PHÍ LAO ĐỘNG TRỰC TIẾP
A16: Lương GĐ + kế toán/năm | B16: =(Dau_vao!B12+Dau_vao!B15)*12 -> 216000000
A17: Lương kỹ thuật trực tiếp Loại 2/năm | B17: =Dau_vao!B13*Dau_vao!B14*12 -> 360000000
A18: Bảo hiểm LĐ trực tiếp Loại 1 | B18: =B16*Dau_vao!B19 -> 46440000
A19: Bảo hiểm LĐ trực tiếp Loại 2 | B19: =(B16+B17)*Dau_vao!B19 -> 123840000
A20: Tổng chi phí lao động trực tiếp Loại 1 | B20: =B16+B18 -> 262440000
A21: Tổng chi phí lao động trực tiếp Loại 2 | B21: =B16+B17+B19 -> 699840000
A22: Chi phí lao động được khấu trừ Loại 1 | B22: =B20*Dau_vao!B20 -> 262440000
A23: Chi phí lao động được khấu trừ Loại 2 | B23: =B21*Dau_vao!B20 -> 699840000
A25: VAT VÀ DÒNG TIỀN
A26: VAT đầu ra | B26: =B6*Dau_vao!B21 -> 160680000
A27: Chi phí có hóa đơn VAT hợp lệ | B27: =SUM(B9:B11)*Dau_vao!B22 -> 132000000
A28: VAT đầu vào được khấu trừ | B28: =B27*Dau_vao!B21 -> 10560000
A29: VAT phải nộp | B29: =MAX(0,B26-B28) -> 150120000
A30: Tổng tiền khách thanh toán gồm VAT | B30: =B6+B26 -> 2169180000
A31: Doanh thu thuần sau bù trừ VAT | B31: =B30-B28-B29 -> 2008500000
A33: CHI PHÍ KÝ HỒ SƠ
A34: Chi phí ký hồ sơ Loại 1 | B34: =B6*Dau_vao!B23 -> 100425000
A35: Chi phí ký hồ sơ được khấu trừ thuế Loại 1 | B35: =B34*Dau_vao!B24 -> 90382500
A36: Chi phí ký hồ sơ Loại 2 | B36: =B6*Dau_vao!B34 -> 40170000
A37: Chi phí ký hồ sơ được khấu trừ thuế Loại 2 | B37: =B36*Dau_vao!B24 -> 36153000

Sheet So_sanh
A1: BẢNG 3 - SO SÁNH KẾT QUẢ 2 LOẠI HỢP ĐỒNG
A3: Chỉ tiêu | B3: Loại 1 | C3: Loại 2
A4: Doanh thu trước VAT | B4: =Tinh_toan!B6 -> 2008500000 | C4: =Tinh_toan!B6 -> 2008500000
A5: VAT đầu ra | B5: =Tinh_toan!B26 -> 160680000 | C5: =Tinh_toan!B26 -> 160680000
A6: Tổng tiền khách thanh toán gồm VAT | B6: =Tinh_toan!B30 -> 2169180000 | C6: =Tinh_toan!B30 -> 2169180000
A7: Cắt lại CĐT không được khấu trừ | B7: =Tinh_toan!B6*Dau_vao!B8 -> 1104675000 | C7: =Tinh_toan!B6*Dau_vao!B9 -> 702975000
A8: Chi phí lao động trực tiếp | B8: =Tinh_toan!B20 -> 262440000 | C8: =Tinh_toan!B21 -> 699840000
A9: Chi phí ký hồ sơ | B9: =Tinh_toan!B34 -> 100425000 | C9: =Tinh_toan!B36 -> 40170000
A10: Chi phí cố định thực chi | B10: =Tinh_toan!B12 -> 132000000 | C10: =Tinh_toan!B12 -> 132000000
A11: Lãi gộp sau cắt lại, lao động và ký hồ sơ | B11: =B4-B7-B8-B9 -> 540960000 | C11: =C4-C7-C8-C9 -> 565515000
A12: Lãi trước thuế theo dòng tiền | B12: =B4-B7-B8-B9-B10 -> 408960000 | C12: =C4-C7-C8-C9-C10 -> 433515000
A13: Chi phí được khấu trừ thuế TNDN | B13: =Tinh_toan!B13+Tinh_toan!B22+Tinh_toan!B35 -> 471622500 | C13: =Tinh_toan!B13+Tinh_toan!B23+Tinh_toan!B37 -> 854793000
A14: Thu nhập chịu thuế TNDN | B14: =B4-B13 -> 1536877500 | C14: =C4-C13 -> 1153707000
A15: Thuế TNDN | B15: =MAX(0,B14*Dau_vao!B10) -> 261269175 | C15: =MAX(0,C14*Dau_vao!B10) -> 196130190
A16: Thuế TNDN / Doanh thu | B16: =B15/B4 -> 0.13008174 | C16: =C15/C4 -> 0.097650082
A17: VAT đầu vào đã trả nhà cung cấp | B17: =Tinh_toan!B28 -> 10560000 | C17: =Tinh_toan!B28 -> 10560000
A18: VAT phải nộp | B18: =Tinh_toan!B29 -> 150120000 | C18: =Tinh_toan!B29 -> 150120000
A19: Lãi ròng sau thuế | B19: =B12-B15 -> 147690825 | C19: =C12-C15 -> 237384810
A20: Lãi ròng/tháng | B20: =B19/12 -> 12307569 | C20: =C19/12 -> 19782068
A21: Biên lãi ròng | B21: =B19/B4 -> 0.073532898 | C21: =C19/C4 -> 0.1181901
A22: Chi phí cố định / Doanh thu | B22: =B10/B4 -> 0.065720687 | C22: =C10/C4 -> 0.065720687
A23: Chi phí lao động trực tiếp / Doanh thu | B23: =B8/B4 -> 0.13066468 | C23: =C8/C4 -> 0.34843913
A24: Dòng tiền sau nộp VAT và thuế TNDN | B24: =B6-B7-B8-B9-B10-B15-B17-B18 -> 147690825 | C24: =C6-C7-C8-C9-C10-C15-C17-C18 -> 237384810
A26: GHI CHÚ CFO
A27: Luong giam doc va ke toan duoc tinh vao chi phi lao dong truc tiep cua ca hai loai hop dong.
A28: Loại 1 khong co luong 2 ky thuat; Loại 2 co them luong 2 ky thuat va bao hiem lien quan.
A29: Chi phí ký hồ sơ: Loại 1 mặc định bằng 5% doanh thu chưa VAT; Loại 2 = 0% (không ap dung), co the dieu chinh tai Dau_vao!B34.
A30: Phần cắt lại CĐT là dòng tiền ra nhưng không được khấu trừ TNDN và không có VAT dau vao de khau tru.

Sheet Phuong_an_toi_uu
A1: PHƯƠNG ÁN TỐI ƯU THUẾ - HỢP THỨC HÓA CHI PHÍ ĐẦU VÀO
A2: Phân tích ngưỡng hòa vốn lãi ròng và đề xuất chi phí hợp lệ để giảm thuế TNDN
A4: I. TÌNH HÌNH HIỆN TẠI (Liên kết từ mô hình gốc)
A5: Chỉ tiêu | B5: Loại 1 | C5: Loại 2 | D5: Đơn vị | E5: Ghi chú
A6: Doanh thu chưa VAT/năm | B6: =So_sanh!B4 -> 2008500000 | C6: =So_sanh!C4 -> 2008500000 | D6: VND
A7: Cắt lại CĐT | B7: =So_sanh!B7 -> 1104675000 | C7: =So_sanh!C7 -> 702975000 | D7: VND | E7: Không được KT thuế
A8: Chi phí lao động TT | B8: =So_sanh!B8 -> 262440000 | C8: =So_sanh!C8 -> 699840000 | D8: VND
A9: Chi phí ký hồ sơ | B9: =So_sanh!B9 -> 100425000 | C9: =So_sanh!C9 -> 40170000 | D9: VND
A10: Chi phí cố định thực chi | B10: =So_sanh!B10 -> 132000000 | C10: =So_sanh!C10 -> 132000000 | D10: VND
A11: Chi phí KT thuế TNDN | B11: =So_sanh!B13 -> 471622500 | C11: =So_sanh!C13 -> 854793000 | D11: VND
A12: Thu nhập chịu thuế | B12: =So_sanh!B14 -> 1536877500 | C12: =So_sanh!C14 -> 1153707000 | D12: VND
A13: Thuế TNDN phải nộp | B13: =So_sanh!B15 -> 261269175 | C13: =So_sanh!C15 -> 196130190 | D13: VND
A14: VAT phải nộp | B14: =So_sanh!B18 -> 150120000 | C14: =So_sanh!C18 -> 150120000 | D14: VND
A15: Lãi ròng sau thuế | B15: =So_sanh!B19 -> 147690825 | C15: =So_sanh!C19 -> 237384810 | D15: VND
A16: Lãi ròng/tháng | B16: =So_sanh!B20 -> 12307569 | C16: =So_sanh!C20 -> 19782068 | D16: VND
A17: Biên lãi ròng | B17: =So_sanh!B21 -> 0.073532898 | C17: =So_sanh!C21 -> 0.1181901 | D17: %
A18: Thuế TNDN / Doanh thu | B18: =So_sanh!B16 -> 0.13008174 | C18: =So_sanh!C16 -> 0.097650082 | D18: %
A20: II. PHÂN TÍCH NGƯỠNG DOANH THU (Điểm lãi ròng = 0)
A21: ⚠ Khi doanh thu giảm tới mức nào thì lãi ròng bắt đầu âm? Phân tích cho cả 2 loại hợp đồng.
A22: Chỉ tiêu | B22: Loại 1 | C22: Loại 2 | D22: Đơn vị | E22: Ghi chú
A23: DT hòa vốn lãi ròng (lý thuyết) | B23: =(Tinh_toan!B20*(1-Dau_vao!B10*Dau_vao!B20)+Tinh_toan!B12*(1-Dau_vao!B10*Dau_vao!B11))/((1-Dau_vao!B8-Dau_vao!B23)-Dau_vao!B10*(1-Dau_vao!B24*Dau_vao!B23)) -> 1387036398 | C23: =(Tinh_toan!B21*(1-Dau_vao!B10*Dau_vao!B20)+Tinh_toan!B12*(1-Dau_vao!B10*Dau_vao!B11))/((1-Dau_vao!B9)-Dau_vao!B10) -> 1443065000 | D23: VND | E23: Dưới mức này lãi ròng âm
A24: % giảm DT so với hiện tại | B24: =(So_sanh!B4-B23)/So_sanh!B4 -> 0.30941678 | C24: =(So_sanh!B4-C23)/So_sanh!B4 -> 0.28152104 | D24: %
A25: Biên độ an toàn (VND) | B25: =So_sanh!B4-B23 -> 6.214636e+08 | C25: =So_sanh!B4-C23 -> 565435000 | D25: VND | E25: Doanh thu hiện tại dư ra so ngưỡng
A26: Biên độ an toàn (%) | B26: =B25/So_sanh!B4 -> 0.30941678 | C26: =C25/So_sanh!B4 -> 0.28152104 | D26: %
A28: III. ĐỀ XUẤT CHI PHÍ ĐẦU VÀO HỢP LỆ ĐỂ GIẢM THUẾ TNDN
A29: 💡 Mục tiêu: Tăng chi phí được khấu trừ thuế để giảm thu nhập chịu thuế xuống mức tối ưu (Lãi ròng mục tiêu nhập ở B31). Các ô màu vàng là đầu vào điều chỉnh được.
A30: Lãi ròng mục tiêu/năm (nhập) | B30: 100000000 | C30: =B30 -> 100000000 | D30: VND | E30: Nhập lãi ròng mục tiêu bạn muốn đạt
A31: Lãi ròng mục tiêu/tháng | B31: =B30/12 -> 8333333.3 | C31: =C30/12 -> 8333333.3 | D31: VND
A33: Hạng mục chi phí | B33: Loại 1 | C33: Loại 2 | D33: Đơn vị | E33: Cơ sở pháp lý / Ghi chú
A34: Chi phí KT thuế hiện tại | B34: =So_sanh!B13 -> 471622500 | C34: =So_sanh!C13 -> 854793000 | D34: VND | E34: Từ mô hình gốc
A35: Thuế TNDN hiện tại | B35: =So_sanh!B15 -> 261269175 | C35: =So_sanh!C15 -> 196130190 | D35: VND
A36: Chi phí cần tăng thêm (hợp lệ) | B36: =MAX(0,(So_sanh!B19-B30)/(1-Dau_vao!B10)) -> 57458825 | C36: =MAX(0,(So_sanh!C19-C30)/(1-Dau_vao!B10)) -> 1.6552387e+08 | D36: VND | E36: (Lãi ròng hiện tại - Mục tiêu) / (1 - thuế TNDN 17%)
A37: Thuế TNDN sau tối ưu | B37: =MAX(0,(So_sanh!B14-B36)*Dau_vao!B10) -> 2.5150117e+08 | C37: =MAX(0,(So_sanh!C14-C36)*Dau_vao!B10) -> 1.6799113e+08 | D37: VND
A38: Thuế tiết kiệm được | B38: =B35-B37 -> 9768000.3 | C38: =C35-C37 -> 28139057 | D38: VND
A40: IV. CÁC PHƯƠNG ÁN HỢP THỨC HÓA CHI PHÍ (Phân bổ chi phí tăng thêm)
A41: Phân bổ chi phí cần tăng thêm (B36/C36) vào các khoản hợp lệ có hóa đơn VAT. Nhập % phân bổ tại cột B (Loại 1) và C (Loại 2). Tổng phải = 100%.
A42: Khoản mục | B42: % phân bổ L1 | C42: % phân bổ L2 | D42: Căn cứ pháp lý | E42: Ghi chú thực tế
A43: 1. Đào tạo & nâng cao năng lực | B43: 0.2 | C43: 0.2 | D43: Điều 4 TT 78/2014 - CP đào tạo | E43: Khóa học PM, BIM, quản lý DA; cần HĐ + chứng chỉ
A44: 2. Thiết bị & phần mềm chuyên ngành | B44: 0.25 | C44: 0.25 | D44: Điều 4 TT 78/2014 - CP công cụ | E44: AutoCAD, Revit, MS Project, máy tính, máy in A0
A45: 3. Chi phí văn phòng & quản lý nâng cao | B45: 0.15 | C45: 0.15 | D45: Điều 4 TT 78/2014 - CP quản lý | E45: Nâng hạng VP, văn phòng phẩm chuyên dụng, bảo hiểm VP
...
